<?xml version="1.0" encoding="UTF-8"?>
<testng-results retried="4" ignored="0" total="5" passed="0" failed="1" skipped="0">
  <reporter-output>
  </reporter-output>
  <suite started-at="2022-01-22T16:42:19 IST" name="Default suite" finished-at="2022-01-22T16:43:24 IST" duration-ms="64470">
    <groups>
    </groups>
    <test started-at="2022-01-22T16:42:19 IST" name="Default test" finished-at="2022-01-22T16:43:24 IST" duration-ms="64470">
      <class name="practice.SampleRetry">
        <test-method is-config="true" signature="ConfigBS()[pri:0, instance:practice.SampleRetry@505fc5a4]" started-at="2022-01-22T16:42:19 IST" name="ConfigBS" finished-at="2022-01-22T16:42:19 IST" duration-ms="14" status="PASS">
          <reporter-output>
          </reporter-output>
        </test-method> <!-- ConfigBS -->
        <test-method is-config="true" signature="ConfigBC()[pri:0, instance:practice.SampleRetry@505fc5a4]" started-at="2022-01-22T16:42:19 IST" name="ConfigBC" finished-at="2022-01-22T16:42:22 IST" duration-ms="2433" status="PASS">
          <reporter-output>
          </reporter-output>
        </test-method> <!-- ConfigBC -->
        <test-method is-config="true" signature="ConfigBM()[pri:0, instance:practice.SampleRetry@505fc5a4]" started-at="2022-01-22T16:42:22 IST" name="ConfigBM" finished-at="2022-01-22T16:42:30 IST" duration-ms="8078" status="PASS">
          <reporter-output>
          </reporter-output>
        </test-method> <!-- ConfigBM -->
        <test-method retried="true" signature="contactTest()[pri:0, instance:practice.SampleRetry@505fc5a4]" started-at="2022-01-22T16:42:30 IST" name="contactTest" finished-at="2022-01-22T16:42:36 IST" duration-ms="6080" status="SKIP">
          <exception class="java.lang.AssertionError">
            <message>
              <![CDATA[expected [B] but found [A]]]>
            </message>
            <full-stacktrace>
              <![CDATA[java.lang.AssertionError: expected [B] but found [A]
at org.testng.Assert.fail(Assert.java:99)
at org.testng.Assert.failNotEquals(Assert.java:1037)
at org.testng.Assert.assertEqualsImpl(Assert.java:140)
at org.testng.Assert.assertEquals(Assert.java:122)
at org.testng.Assert.assertEquals(Assert.java:629)
at org.testng.Assert.assertEquals(Assert.java:639)
at practice.SampleRetry.contactTest(SampleRetry.java:17)
at java.base/jdk.internal.reflect.NativeMethodAccessorImpl.invoke0(Native Method)
at java.base/jdk.internal.reflect.NativeMethodAccessorImpl.invoke(NativeMethodAccessorImpl.java:77)
at java.base/jdk.internal.reflect.DelegatingMethodAccessorImpl.invoke(DelegatingMethodAccessorImpl.java:43)
at java.base/java.lang.reflect.Method.invoke(Method.java:568)
at org.testng.internal.MethodInvocationHelper.invokeMethod(MethodInvocationHelper.java:133)
at org.testng.internal.TestInvoker.invokeMethod(TestInvoker.java:598)
at org.testng.internal.TestInvoker.invokeTestMethod(TestInvoker.java:173)
at org.testng.internal.MethodRunner.runInSequence(MethodRunner.java:46)
at org.testng.internal.TestInvoker$MethodInvocationAgent.invoke(TestInvoker.java:824)
at org.testng.internal.TestInvoker.invokeTestMethods(TestInvoker.java:146)
at org.testng.internal.TestMethodWorker.invokeTestMethods(TestMethodWorker.java:146)
at org.testng.internal.TestMethodWorker.run(TestMethodWorker.java:128)
at java.base/java.util.ArrayList.forEach(ArrayList.java:1511)
at org.testng.TestRunner.privateRun(TestRunner.java:794)
at org.testng.TestRunner.run(TestRunner.java:596)
at org.testng.SuiteRunner.runTest(SuiteRunner.java:377)
at org.testng.SuiteRunner.runSequentially(SuiteRunner.java:371)
at org.testng.SuiteRunner.privateRun(SuiteRunner.java:332)
at org.testng.SuiteRunner.run(SuiteRunner.java:276)
at org.testng.SuiteRunnerWorker.runSuite(SuiteRunnerWorker.java:53)
at org.testng.SuiteRunnerWorker.run(SuiteRunnerWorker.java:96)
at org.testng.TestNG.runSuitesSequentially(TestNG.java:1212)
at org.testng.TestNG.runSuitesLocally(TestNG.java:1134)
at org.testng.TestNG.runSuites(TestNG.java:1063)
at org.testng.TestNG.run(TestNG.java:1031)
at org.testng.remote.AbstractRemoteTestNG.run(AbstractRemoteTestNG.java:115)
at org.testng.remote.RemoteTestNG.initAndRun(RemoteTestNG.java:251)
at org.testng.remote.RemoteTestNG.main(RemoteTestNG.java:77)
]]>
            </full-stacktrace>
          </exception> <!-- java.lang.AssertionError -->
          <reporter-output>
          </reporter-output>
        </test-method> <!-- contactTest -->
        <test-method is-config="true" signature="ConfigAM()[pri:0, instance:practice.SampleRetry@505fc5a4]" started-at="2022-01-22T16:42:36 IST" name="ConfigAM" finished-at="2022-01-22T16:42:38 IST" duration-ms="1598" status="PASS">
          <reporter-output>
          </reporter-output>
        </test-method> <!-- ConfigAM -->
        <test-method is-config="true" signature="ConfigBM()[pri:0, instance:practice.SampleRetry@505fc5a4]" started-at="2022-01-22T16:42:38 IST" name="ConfigBM" finished-at="2022-01-22T16:42:42 IST" duration-ms="3971" status="PASS">
          <reporter-output>
          </reporter-output>
        </test-method> <!-- ConfigBM -->
        <test-method retried="true" signature="contactTest()[pri:0, instance:practice.SampleRetry@505fc5a4]" started-at="2022-01-22T16:42:42 IST" name="contactTest" finished-at="2022-01-22T16:42:48 IST" duration-ms="6629" status="SKIP">
          <exception class="java.lang.AssertionError">
            <message>
              <![CDATA[expected [B] but found [A]]]>
            </message>
            <full-stacktrace>
              <![CDATA[java.lang.AssertionError: expected [B] but found [A]
at org.testng.Assert.fail(Assert.java:99)
at org.testng.Assert.failNotEquals(Assert.java:1037)
at org.testng.Assert.assertEqualsImpl(Assert.java:140)
at org.testng.Assert.assertEquals(Assert.java:122)
at org.testng.Assert.assertEquals(Assert.java:629)
at org.testng.Assert.assertEquals(Assert.java:639)
at practice.SampleRetry.contactTest(SampleRetry.java:17)
at java.base/jdk.internal.reflect.NativeMethodAccessorImpl.invoke0(Native Method)
at java.base/jdk.internal.reflect.NativeMethodAccessorImpl.invoke(NativeMethodAccessorImpl.java:77)
at java.base/jdk.internal.reflect.DelegatingMethodAccessorImpl.invoke(DelegatingMethodAccessorImpl.java:43)
at java.base/java.lang.reflect.Method.invoke(Method.java:568)
at org.testng.internal.MethodInvocationHelper.invokeMethod(MethodInvocationHelper.java:133)
at org.testng.internal.TestInvoker.invokeMethod(TestInvoker.java:598)
at org.testng.internal.TestInvoker.retryFailed(TestInvoker.java:213)
at org.testng.internal.MethodRunner.runInSequence(MethodRunner.java:58)
at org.testng.internal.TestInvoker$MethodInvocationAgent.invoke(TestInvoker.java:824)
at org.testng.internal.TestInvoker.invokeTestMethods(TestInvoker.java:146)
at org.testng.internal.TestMethodWorker.invokeTestMethods(TestMethodWorker.java:146)
at org.testng.internal.TestMethodWorker.run(TestMethodWorker.java:128)
at java.base/java.util.ArrayList.forEach(ArrayList.java:1511)
at org.testng.TestRunner.privateRun(TestRunner.java:794)
at org.testng.TestRunner.run(TestRunner.java:596)
at org.testng.SuiteRunner.runTest(SuiteRunner.java:377)
at org.testng.SuiteRunner.runSequentially(SuiteRunner.java:371)
at org.testng.SuiteRunner.privateRun(SuiteRunner.java:332)
at org.testng.SuiteRunner.run(SuiteRunner.java:276)
at org.testng.SuiteRunnerWorker.runSuite(SuiteRunnerWorker.java:53)
at org.testng.SuiteRunnerWorker.run(SuiteRunnerWorker.java:96)
at org.testng.TestNG.runSuitesSequentially(TestNG.java:1212)
at org.testng.TestNG.runSuitesLocally(TestNG.java:1134)
at org.testng.TestNG.runSuites(TestNG.java:1063)
at org.testng.TestNG.run(TestNG.java:1031)
at org.testng.remote.AbstractRemoteTestNG.run(AbstractRemoteTestNG.java:115)
at org.testng.remote.RemoteTestNG.initAndRun(RemoteTestNG.java:251)
at org.testng.remote.RemoteTestNG.main(RemoteTestNG.java:77)
]]>
            </full-stacktrace>
          </exception> <!-- java.lang.AssertionError -->
          <reporter-output>
          </reporter-output>
        </test-method> <!-- contactTest -->
        <test-method is-config="true" signature="ConfigAM()[pri:0, instance:practice.SampleRetry@505fc5a4]" started-at="2022-01-22T16:42:48 IST" name="ConfigAM" finished-at="2022-01-22T16:42:50 IST" duration-ms="1502" status="PASS">
          <reporter-output>
          </reporter-output>
        </test-method> <!-- ConfigAM -->
        <test-method is-config="true" signature="ConfigBM()[pri:0, instance:practice.SampleRetry@505fc5a4]" started-at="2022-01-22T16:42:50 IST" name="ConfigBM" finished-at="2022-01-22T16:42:53 IST" duration-ms="3369" status="PASS">
          <reporter-output>
          </reporter-output>
        </test-method> <!-- ConfigBM -->
        <test-method retried="true" signature="contactTest()[pri:0, instance:practice.SampleRetry@505fc5a4]" started-at="2022-01-22T16:42:53 IST" name="contactTest" finished-at="2022-01-22T16:42:59 IST" duration-ms="5698" status="SKIP">
          <exception class="java.lang.AssertionError">
            <message>
              <![CDATA[expected [B] but found [A]]]>
            </message>
            <full-stacktrace>
              <![CDATA[java.lang.AssertionError: expected [B] but found [A]
at org.testng.Assert.fail(Assert.java:99)
at org.testng.Assert.failNotEquals(Assert.java:1037)
at org.testng.Assert.assertEqualsImpl(Assert.java:140)
at org.testng.Assert.assertEquals(Assert.java:122)
at org.testng.Assert.assertEquals(Assert.java:629)
at org.testng.Assert.assertEquals(Assert.java:639)
at practice.SampleRetry.contactTest(SampleRetry.java:17)
at java.base/jdk.internal.reflect.NativeMethodAccessorImpl.invoke0(Native Method)
at java.base/jdk.internal.reflect.NativeMethodAccessorImpl.invoke(NativeMethodAccessorImpl.java:77)
at java.base/jdk.internal.reflect.DelegatingMethodAccessorImpl.invoke(DelegatingMethodAccessorImpl.java:43)
at java.base/java.lang.reflect.Method.invoke(Method.java:568)
at org.testng.internal.MethodInvocationHelper.invokeMethod(MethodInvocationHelper.java:133)
at org.testng.internal.TestInvoker.invokeMethod(TestInvoker.java:598)
at org.testng.internal.TestInvoker.retryFailed(TestInvoker.java:213)
at org.testng.internal.MethodRunner.runInSequence(MethodRunner.java:58)
at org.testng.internal.TestInvoker$MethodInvocationAgent.invoke(TestInvoker.java:824)
at org.testng.internal.TestInvoker.invokeTestMethods(TestInvoker.java:146)
at org.testng.internal.TestMethodWorker.invokeTestMethods(TestMethodWorker.java:146)
at org.testng.internal.TestMethodWorker.run(TestMethodWorker.java:128)
at java.base/java.util.ArrayList.forEach(ArrayList.java:1511)
at org.testng.TestRunner.privateRun(TestRunner.java:794)
at org.testng.TestRunner.run(TestRunner.java:596)
at org.testng.SuiteRunner.runTest(SuiteRunner.java:377)
at org.testng.SuiteRunner.runSequentially(SuiteRunner.java:371)
at org.testng.SuiteRunner.privateRun(SuiteRunner.java:332)
at org.testng.SuiteRunner.run(SuiteRunner.java:276)
at org.testng.SuiteRunnerWorker.runSuite(SuiteRunnerWorker.java:53)
at org.testng.SuiteRunnerWorker.run(SuiteRunnerWorker.java:96)
at org.testng.TestNG.runSuitesSequentially(TestNG.java:1212)
at org.testng.TestNG.runSuitesLocally(TestNG.java:1134)
at org.testng.TestNG.runSuites(TestNG.java:1063)
at org.testng.TestNG.run(TestNG.java:1031)
at org.testng.remote.AbstractRemoteTestNG.run(AbstractRemoteTestNG.java:115)
at org.testng.remote.RemoteTestNG.initAndRun(RemoteTestNG.java:251)
at org.testng.remote.RemoteTestNG.main(RemoteTestNG.java:77)
]]>
            </full-stacktrace>
          </exception> <!-- java.lang.AssertionError -->
          <reporter-output>
          </reporter-output>
        </test-method> <!-- contactTest -->
        <test-method is-config="true" signature="ConfigAM()[pri:0, instance:practice.SampleRetry@505fc5a4]" started-at="2022-01-22T16:42:59 IST" name="ConfigAM" finished-at="2022-01-22T16:43:01 IST" duration-ms="1786" status="PASS">
          <reporter-output>
          </reporter-output>
        </test-method> <!-- ConfigAM -->
        <test-method is-config="true" signature="ConfigBM()[pri:0, instance:practice.SampleRetry@505fc5a4]" started-at="2022-01-22T16:43:01 IST" name="ConfigBM" finished-at="2022-01-22T16:43:04 IST" duration-ms="3797" status="PASS">
          <reporter-output>
          </reporter-output>
        </test-method> <!-- ConfigBM -->
        <test-method retried="true" signature="contactTest()[pri:0, instance:practice.SampleRetry@505fc5a4]" started-at="2022-01-22T16:43:04 IST" name="contactTest" finished-at="2022-01-22T16:43:10 IST" duration-ms="5597" status="SKIP">
          <exception class="java.lang.AssertionError">
            <message>
              <![CDATA[expected [B] but found [A]]]>
            </message>
            <full-stacktrace>
              <![CDATA[java.lang.AssertionError: expected [B] but found [A]
at org.testng.Assert.fail(Assert.java:99)
at org.testng.Assert.failNotEquals(Assert.java:1037)
at org.testng.Assert.assertEqualsImpl(Assert.java:140)
at org.testng.Assert.assertEquals(Assert.java:122)
at org.testng.Assert.assertEquals(Assert.java:629)
at org.testng.Assert.assertEquals(Assert.java:639)
at practice.SampleRetry.contactTest(SampleRetry.java:17)
at java.base/jdk.internal.reflect.NativeMethodAccessorImpl.invoke0(Native Method)
at java.base/jdk.internal.reflect.NativeMethodAccessorImpl.invoke(NativeMethodAccessorImpl.java:77)
at java.base/jdk.internal.reflect.DelegatingMethodAccessorImpl.invoke(DelegatingMethodAccessorImpl.java:43)
at java.base/java.lang.reflect.Method.invoke(Method.java:568)
at org.testng.internal.MethodInvocationHelper.invokeMethod(MethodInvocationHelper.java:133)
at org.testng.internal.TestInvoker.invokeMethod(TestInvoker.java:598)
at org.testng.internal.TestInvoker.retryFailed(TestInvoker.java:213)
at org.testng.internal.MethodRunner.runInSequence(MethodRunner.java:58)
at org.testng.internal.TestInvoker$MethodInvocationAgent.invoke(TestInvoker.java:824)
at org.testng.internal.TestInvoker.invokeTestMethods(TestInvoker.java:146)
at org.testng.internal.TestMethodWorker.invokeTestMethods(TestMethodWorker.java:146)
at org.testng.internal.TestMethodWorker.run(TestMethodWorker.java:128)
at java.base/java.util.ArrayList.forEach(ArrayList.java:1511)
at org.testng.TestRunner.privateRun(TestRunner.java:794)
at org.testng.TestRunner.run(TestRunner.java:596)
at org.testng.SuiteRunner.runTest(SuiteRunner.java:377)
at org.testng.SuiteRunner.runSequentially(SuiteRunner.java:371)
at org.testng.SuiteRunner.privateRun(SuiteRunner.java:332)
at org.testng.SuiteRunner.run(SuiteRunner.java:276)
at org.testng.SuiteRunnerWorker.runSuite(SuiteRunnerWorker.java:53)
at org.testng.SuiteRunnerWorker.run(SuiteRunnerWorker.java:96)
at org.testng.TestNG.runSuitesSequentially(TestNG.java:1212)
at org.testng.TestNG.runSuitesLocally(TestNG.java:1134)
at org.testng.TestNG.runSuites(TestNG.java:1063)
at org.testng.TestNG.run(TestNG.java:1031)
at org.testng.remote.AbstractRemoteTestNG.run(AbstractRemoteTestNG.java:115)
at org.testng.remote.RemoteTestNG.initAndRun(RemoteTestNG.java:251)
at org.testng.remote.RemoteTestNG.main(RemoteTestNG.java:77)
]]>
            </full-stacktrace>
          </exception> <!-- java.lang.AssertionError -->
          <reporter-output>
          </reporter-output>
        </test-method> <!-- contactTest -->
        <test-method is-config="true" signature="ConfigAM()[pri:0, instance:practice.SampleRetry@505fc5a4]" started-at="2022-01-22T16:43:10 IST" name="ConfigAM" finished-at="2022-01-22T16:43:12 IST" duration-ms="1717" status="PASS">
          <reporter-output>
          </reporter-output>
        </test-method> <!-- ConfigAM -->
        <test-method is-config="true" signature="ConfigBM()[pri:0, instance:practice.SampleRetry@505fc5a4]" started-at="2022-01-22T16:43:12 IST" name="ConfigBM" finished-at="2022-01-22T16:43:15 IST" duration-ms="3563" status="PASS">
          <reporter-output>
          </reporter-output>
        </test-method> <!-- ConfigBM -->
        <test-method signature="contactTest()[pri:0, instance:practice.SampleRetry@505fc5a4]" started-at="2022-01-22T16:43:15 IST" name="contactTest" finished-at="2022-01-22T16:43:22 IST" duration-ms="6491" status="FAIL">
          <exception class="java.lang.AssertionError">
            <message>
              <![CDATA[expected [B] but found [A]]]>
            </message>
            <full-stacktrace>
              <![CDATA[java.lang.AssertionError: expected [B] but found [A]
at org.testng.Assert.fail(Assert.java:99)
at org.testng.Assert.failNotEquals(Assert.java:1037)
at org.testng.Assert.assertEqualsImpl(Assert.java:140)
at org.testng.Assert.assertEquals(Assert.java:122)
at org.testng.Assert.assertEquals(Assert.java:629)
at org.testng.Assert.assertEquals(Assert.java:639)
at practice.SampleRetry.contactTest(SampleRetry.java:17)
at java.base/jdk.internal.reflect.NativeMethodAccessorImpl.invoke0(Native Method)
at java.base/jdk.internal.reflect.NativeMethodAccessorImpl.invoke(NativeMethodAccessorImpl.java:77)
at java.base/jdk.internal.reflect.DelegatingMethodAccessorImpl.invoke(DelegatingMethodAccessorImpl.java:43)
at java.base/java.lang.reflect.Method.invoke(Method.java:568)
at org.testng.internal.MethodInvocationHelper.invokeMethod(MethodInvocationHelper.java:133)
at org.testng.internal.TestInvoker.invokeMethod(TestInvoker.java:598)
at org.testng.internal.TestInvoker.retryFailed(TestInvoker.java:213)
at org.testng.internal.MethodRunner.runInSequence(MethodRunner.java:58)
at org.testng.internal.TestInvoker$MethodInvocationAgent.invoke(TestInvoker.java:824)
at org.testng.internal.TestInvoker.invokeTestMethods(TestInvoker.java:146)
at org.testng.internal.TestMethodWorker.invokeTestMethods(TestMethodWorker.java:146)
at org.testng.internal.TestMethodWorker.run(TestMethodWorker.java:128)
at java.base/java.util.ArrayList.forEach(ArrayList.java:1511)
at org.testng.TestRunner.privateRun(TestRunner.java:794)
at org.testng.TestRunner.run(TestRunner.java:596)
at org.testng.SuiteRunner.runTest(SuiteRunner.java:377)
at org.testng.SuiteRunner.runSequentially(SuiteRunner.java:371)
at org.testng.SuiteRunner.privateRun(SuiteRunner.java:332)
at org.testng.SuiteRunner.run(SuiteRunner.java:276)
at org.testng.SuiteRunnerWorker.runSuite(SuiteRunnerWorker.java:53)
at org.testng.SuiteRunnerWorker.run(SuiteRunnerWorker.java:96)
at org.testng.TestNG.runSuitesSequentially(TestNG.java:1212)
at org.testng.TestNG.runSuitesLocally(TestNG.java:1134)
at org.testng.TestNG.runSuites(TestNG.java:1063)
at org.testng.TestNG.run(TestNG.java:1031)
at org.testng.remote.AbstractRemoteTestNG.run(AbstractRemoteTestNG.java:115)
at org.testng.remote.RemoteTestNG.initAndRun(RemoteTestNG.java:251)
at org.testng.remote.RemoteTestNG.main(RemoteTestNG.java:77)
]]>
            </full-stacktrace>
          </exception> <!-- java.lang.AssertionError -->
          <reporter-output>
          </reporter-output>
        </test-method> <!-- contactTest -->
        <test-method is-config="true" signature="ConfigAM()[pri:0, instance:practice.SampleRetry@505fc5a4]" started-at="2022-01-22T16:43:22 IST" name="ConfigAM" finished-at="2022-01-22T16:43:24 IST" duration-ms="1971" status="PASS">
          <reporter-output>
          </reporter-output>
        </test-method> <!-- ConfigAM -->
        <test-method is-config="true" signature="ConfigAC()[pri:0, instance:practice.SampleRetry@505fc5a4]" started-at="2022-01-22T16:43:24 IST" name="ConfigAC" finished-at="2022-01-22T16:43:24 IST" duration-ms="114" status="PASS">
          <reporter-output>
          </reporter-output>
        </test-method> <!-- ConfigAC -->
        <test-method is-config="true" signature="ConfigAS()[pri:0, instance:practice.SampleRetry@505fc5a4]" started-at="2022-01-22T16:43:24 IST" name="ConfigAS" finished-at="2022-01-22T16:43:24 IST" duration-ms="1" status="PASS">
          <reporter-output>
          </reporter-output>
        </test-method> <!-- ConfigAS -->
      </class> <!-- practice.SampleRetry -->
    </test> <!-- Default test -->
  </suite> <!-- Default suite -->
</testng-results>
